<?xml version="1.0"?>
<robot name="four_wheel_robot">
  <link name="base_link">
    <inertial>
      <mass value="10"/>
      <origin rpy="0 0 0" xyz="0 0 0"/>
      <inertia ixx="1" ixy="0" ixz="0" iyy="1" iyz="0" izz="1"/>
    </inertial>
    <collision>
      <geometry>
        <box size="0.5 0.5 0.1"/>
      </geometry>
    </collision>
    <visual>
      <geometry>
        <box size="0.5 0.5 0.1"/>
      </geometry>
    </visual>
  </link>

  <joint name="front_left_wheel_joint" type="continuous">
    <parent link="base_link"/>
    <child link="front_left_wheel"/>
    <origin rpy="0 0 0" xyz="0.25 0.25 0"/>
    <axis xyz="0 0 1"/>
  </joint>
  <link name="front_left_wheel">
    <inertial>
      <mass value="1"/>
      <origin rpy="0 0 0" xyz="0 0 0"/>
      <inertia ixx="0.02" ixy="0" ixz="0" iyy="0.02" iyz="0" izz="0.04"/>
    </inertial>
    <collision>
      <geometry>
        <cylinder length="0.1" radius="0.05"/>
      </geometry>
    </collision>
    <visual>
      <geometry>
        <cylinder length="0.1" radius="0.05"/>
      </geometry>
    </visual>
  </link>

  <joint name="front_right_wheel_joint" type="continuous">
    <parent link="base_link"/>
    <child link="front_right_wheel"/>
    <origin rpy="0 0 0" xyz="0.25 -0.25 0"/>
    <axis xyz="0 0 1"/>
  </joint>
  <link name="front_right_wheel">
    <inertial>
      <mass value="1"/>
      <origin rpy="0 0 0" xyz="0 0 0"/>
      <inertia ixx="0.02" ixy="0" ixz="0" iyy="0.02" iyz="0" izz="0.04"/>
    </inertial>
    <collision>
      <geometry>
        <cylinder length="0.1" radius="0.05"/>
      </geometry>
    </collision>
    <visual>
      <geometry>
        <cylinder length="0.1" radius="0.05"/>
      </geometry>
    </visual>
  </link>

  <joint name="rear_left_wheel_joint" type="continuous">
    <parent link="base_link"/>
    <child link="rear_left_wheel"/>
    <origin rpy="0 0 0" xyz="-0.25 0 0"/>
    <inertial>
      <mass value="1"/>
      <origin rpy="0 0 0" xyz="0 0 0"/>
      <inertia ixx="0.02" ixy="0" ixz="0" iyy="0.02" iyz="0" izz="0.04"/>
    </inertial>
    <collision>
      <geometry>
        <cylinder length="0.1" radius="0.05"/>
      </geometry>
    </collision>
    <visual>
      <geometry>
        <cylinder length="0.1" radius="0.05"/>
      </geometry>
    </visual>
  </link>
  <joint name="rear_right_wheel_joint" type="continuous">
    <parent link="base_link"/>
    <child link="rear_right_wheel"/>
    <origin rpy="0 0 0" xyz="-0.25 -0.25 0"/>
    <axis xyz="0 0 1"/>
  </joint>
  <link name="rear_right_wheel">
    <inertial>
      <mass value="1"/>
      <origin rpy="0 0 0" xyz="0 0 0"/>
      <inertia ixx="0.02" ixy="0" ixz="0" iyy="0.02" iyz="0" izz="0.04"/>
    </inertial>
    <collision>
      <geometry>
        <cylinder length="0.1" radius="0.05"/>
      </geometry>
    </collision>
    <visual>
      <geometry>
        <cylinder length="0.1" radius="0.05"/>
      </geometry>
    </visual>
  </link>
</robot>


